Workbook

Sheet Cover
B3: KSESTOR
B4: MONTHLY SALES REPORT
B5: Interactive performance monitoring · Amazon US/CA/UK · TikTok Shop · Shopify & Faire · Walmart
B8: WORKBOOK MAP
B10: # | C10: Sheet | D10: What you'll find
B11: 01 | C11: Cover | D11: This page
B12: 02 | C12: Executive Summary | D12: Month/Year selectors · full annual view below
B13: 03 | C13: Amazon Dashboard | D13: Country dropdown (US/CA/UK) · KPIs · monthly trend with year selector · expandable breakdown
B14: 04 | C14: TikTok Dashboard | D14: KPIs · monthly trend with year selector · expandable breakdown
B15: 05 | C15: Shopify Dashboard | D15: KPIs · monthly trend with year selector · expandable breakdown
B16: 06 | C16: Walmart Dashboard | D16: KPIs · monthly trend with year selector · expandable breakdown
B17: 07 | C17: Monthly Data | D17: Month-over-month totals for every marketplace
B18: 08 | C18: Sales Data | D18: Raw · colored headers by marketplace · soft-blue entry cells
B19: 09 | C19: Main Expenses | D19: Raw expense data · main category
B20: 10 | C20: Sub Expenses | D20: Raw expense data · sub category
B21: 11 | C21: Setup | D21: Dropdown lists · do not edit
B24: How to use
B25: • Use dropdowns at top of each dashboard — Month, Year, Country.
B26: • Every KPI is driven by SUMIFS formulas. Change selectors — numbers refresh automatically.
B27: • The Monthly Trend section has its own Year dropdown.
B28: • Enter new data in soft-blue cells on Sales Data and Expenses sheets.
B29: • In Expense Breakdown, click the + icon on the left margin of each main category row to expand sub-categories.
B30: • Amazon dashboard supports US, CA, and UK — switch via the Marketplace dropdown.
B32: Generated April 24, 2026 · Prepared for Kseniia · KSESTOR

Sheet Executive Summary
B2: EXECUTIVE SUMMARY
B3: Cross-marketplace monitoring · pick month & year for snapshot · full annual view below.
B6: MONTH | C6: YEAR
B7: Mar | C7: 2026
B10: MONTHLY SNAPSHOT · ALL MARKETPLACES
B11: Marketplace | C11: Sales (USD) | D11: Expenses (USD) | E11: Net Profit | F11: Margin % | G11: Sales %
B12: Amazon US | C12: =SUMIFS('Sales Data'!$E$6:$E$10000,'Sales Data'!$B$6:$B$10000,"Amazon US",'Sales Data'!$BC$6:$BC$10000,$B$7,'Sales Data'!$BD$6:$BD$10000,$C$7) | D12: =SUMIFS('Main Expenses'!$E$6:$E$10000,'Main Expenses'!$B$6:$B$10000,"Amazon US",'Main Expenses'!$K$6:$K$10000,$B$7,'Main Expenses'!$L$6:$L$10000,$C$7) | E12: =C12+D12 | F12: =IFERROR(E12/C12,0) | G12: =IFERROR(C12/SUMIFS('Sales Data'!$E$6:$E$10000,'Sales Data'!$BC$6:$BC$10000,$B$7,'Sales Data'!$BD$6:$BD$10000,$C$7),0)
B13: Amazon CA | C13: =SUMIFS('Sales Data'!$E$6:$E$10000,'Sales Data'!$B$6:$B$10000,"Amazon CA",'Sales Data'!$BC$6:$BC$10000,$B$7,'Sales Data'!$BD$6:$BD$10000,$C$7) | D13: =SUMIFS('Main Expenses'!$E$6:$E$10000,'Main Expenses'!$B$6:$B$10000,"Amazon CA",'Main Expenses'!$K$6:$K$10000,$B$7,'Main Expenses'!$L$6:$L$10000,$C$7) | E13: =C13+D13 | F13: =IFERROR(E13/C13,0) | G13: =IFERROR(C13/SUMIFS('Sales Data'!$E$6:$E$10000,'Sales Data'!$BC$6:$BC$10000,$B$7,'Sales Data'!$BD$6:$BD$10000,$C$7),0)
B14: Amazon UK | C14: =SUMIFS('Sales Data'!$E$6:$E$10000,'Sales Data'!$B$6:$B$10000,"Amazon UK",'Sales Data'!$BC$6:$BC$10000,$B$7,'Sales Data'!$BD$6:$BD$10000,$C$7) | D14: =SUMIFS('Main Expenses'!$E$6:$E$10000,'Main Expenses'!$B$6:$B$10000,"Amazon UK",'Main Expenses'!$K$6:$K$10000,$B$7,'Main Expenses'!$L$6:$L$10000,$C$7) | E14: =C14+D14 | F14: =IFERROR(E14/C14,0) | G14: =IFERROR(C14/SUMIFS('Sales Data'!$E$6:$E$10000,'Sales Data'!$BC$6:$BC$10000,$B$7,'Sales Data'!$BD$6:$BD$10000,$C$7),0)
B15: TikTok Shop | C15: =SUMIFS('Sales Data'!$E$6:$E$10000,'Sales Data'!$B$6:$B$10000,"Tiktok",'Sales Data'!$BC$6:$BC$10000,$B$7,'Sales Data'!$BD$6:$BD$10000,$C$7) | D15: =SUMIFS('Main Expenses'!$E$6:$E$10000,'Main Expenses'!$B$6:$B$10000,"Tiktok",'Main Expenses'!$K$6:$K$10000,$B$7,'Main Expenses'!$L$6:$L$10000,$C$7) | E15: =C15+D15 | F15: =IFERROR(E15/C15,0) | G15: =IFERROR(C15/SUMIFS('Sales Data'!$E$6:$E$10000,'Sales Data'!$BC$6:$BC$10000,$B$7,'Sales Data'!$BD$6:$BD$10000,$C$7),0)
B16: Shopify & Faire | C16: =SUMIFS('Sales Data'!$E$6:$E$10000,'Sales Data'!$B$6:$B$10000,"Shopify",'Sales Data'!$BC$6:$BC$10000,$B$7,'Sales Data'!$BD$6:$BD$10000,$C$7) | D16: =SUMIFS('Main Expenses'!$E$6:$E$10000,'Main Expenses'!$B$6:$B$10000,"Shopify",'Main Expenses'!$K$6:$K$10000,$B$7,'Main Expenses'!$L$6:$L$10000,$C$7) | E16: =C16+D16 | F16: =IFERROR(E16/C16,0) | G16: =IFERROR(C16/SUMIFS('Sales Data'!$E$6:$E$10000,'Sales Data'!$BC$6:$BC$10000,$B$7,'Sales Data'!$BD$6:$BD$10000,$C$7),0)
B17: Walmart | C17: =SUMIFS('Sales Data'!$E$6:$E$10000,'Sales Data'!$B$6:$B$10000,"Walmart",'Sales Data'!$BC$6:$BC$10000,$B$7,'Sales Data'!$BD$6:$BD$10000,$C$7) | D17: =SUMIFS('Main Expenses'!$E$6:$E$10000,'Main Expenses'!$B$6:$B$10000,"Walmart",'Main Expenses'!$K$6:$K$10000,$B$7,'Main Expenses'!$L$6:$L$10000,$C$7) | E17: =C17+D17 | F17: =IFERROR(E17/C17,0) | G17: =IFERROR(C17/SUMIFS('Sales Data'!$E$6:$E$10000,'Sales Data'!$BC$6:$BC$10000,$B$7,'Sales Data'!$BD$6:$BD$10000,$C$7),0)
B18: TOTAL | C18: =SUM(C12:C17) | D18: =SUM(D12:D17) | E18: =SUM(E12:E17) | F18: =IFERROR(E18/C18,0) | G18: 1
B21: FULL YEAR VIEW · MONTHLY TRENDS | N21: Year: | O21: 2026
B23: MARKETPLACE | C23: METRIC | D23: Jan | E23: Feb | F23: Mar | G23: Apr | H23: May | I23: Jun | J23: Jul | K23: Aug | L23: Sep | M23: Oct | N23: Nov | O23: Dec | P23: YEAR TOTAL
B24: Amazon US | C24: Sales | D24: =SUMIFS('Sales Data'!$E$6:$E$10000,'Sales Data'!$B$6:$B$10000,"Amazon US",'Sales Data'!$BC$6:$BC$10000,"Jan",'Sales Data'!$BD$6:$BD$10000,$O$21) | E24: =SUMIFS('Sales Data'!$E$6:$E$10000,'Sales Data'!$B$6:$B$10000,"Amazon US",'Sales Data'!$BC$6:$BC$10000,"Feb",'Sales Data'!$BD$6:$BD$10000,$O$21) | F24: =SUMIFS('Sales Data'!$E$6:$E$10000,'Sales Data'!$B$6:$B$10000,"Amazon US",'Sales Data'!$BC$6:$BC$10000,"Mar",'Sales Data'!$BD$6:$BD$10000,$O$21) | G24: =SUMIFS('Sales Data'!$E$6:$E$10000,'Sales Data'!$B$6:$B$10000,"Amazon US",'Sales Data'!$BC$6:$BC$10000,"Apr",'Sales Data'!$BD$6:$BD$10000,$O$21) | H24: =SUMIFS('Sales Data'!$E$6:$E$10000,'Sales Data'!$B$6:$B$10000,"Amazon US",'Sales Data'!$BC$6:$BC$10000,"May",'Sales Data'!$BD$6:$BD$10000,$O$21) | I24: =SUMIFS('Sales Data'!$E$6:$E$10000,'Sales Data'!$B$6:$B$10000,"Amazon US",'Sales Data'!$BC$6:$BC$10000,"Jun",'Sales Data'!$BD$6:$BD$10000,$O$21) | J24: =SUMIFS('Sales Data'!$E$6:$E$10000,'Sales Data'!$B$6:$B$10000,"Amazon US",'Sales Data'!$BC$6:$BC$10000,"Jul",'Sales Data'!$BD$6:$BD$10000,$O$21) | K24: =SUMIFS('Sales Data'!$E$6:$E$10000,'Sales Data'!$B$6:$B$10000,"Amazon US",'Sales Data'!$BC$6:$BC$10000,"Aug",'Sales Data'!$BD$6:$BD$10000,$O$21) | L24: =SUMIFS('Sales Data'!$E$6:$E$10000,'Sales Data'!$B$6:$B$10000,"Amazon US",'Sales Data'!$BC$6:$BC$10000,"Sep",'Sales Data'!$BD$6:$BD$10000,$O$21) | M24: =SUMIFS('Sales Data'!$E$6:$E$10000,'Sales Data'!$B$6:$B$10000,"Amazon US",'Sales Data'!$BC$6:$BC$10000,"Oct",'Sales Data'!$BD$6:$BD$10000,$O$21) | N24: =SUMIFS('Sales Data'!$E$6:$E$10000,'Sales Data'!$B$6:$B$10000,"Amazon US",'Sales Data'!$BC$6:$BC$10000,"Nov",'Sales Data'!$BD$6:$BD$10000,$O$21) | O24: =SUMIFS('Sales Data'!$E$6:$E$10000,'Sales Data'!$B$6:$B$10000,"Amazon US",'Sales Data'!$BC$6:$BC$10000,"Dec",'Sales Data'!$BD$6:$BD$10000,$O$21) | P24: =SUM(D24:O24)
C25: Expenses | D25: =SUMIFS('Main Expenses'!$E$6:$E$10000,'Main Expenses'!$B$6:$B$10000,"Amazon US",'Main Expenses'!$K$6:$K$10000,"Jan",'Main Expenses'!$L$6:$L$10000,$O$21) | E25: =SUMIFS('Main Expenses'!$E$6:$E$10000,'Main Expenses'!$B$6:$B$10000,"Amazon US",'Main Expenses'!$K$6:$K$10000,"Feb",'Main Expenses'!$L$6:$L$10000,$O$21) | F25: =SUMIFS('Main Expenses'!$E$6:$E$10000,'Main Expenses'!$B$6:$B$10000,"Amazon US",'Main Expenses'!$K$6:$K$10000,"Mar",'Main Expenses'!$L$6:$L$10000,$O$21) | G25: =SUMIFS('Main Expenses'!$E$6:$E$10000,'Main Expenses'!$B$6:$B$10000,"Amazon US",'Main Expenses'!$K$6:$K$10000,"Apr",'Main Expenses'!$L$6:$L$10000,$O$21) | H25: =SUMIFS('Main Expenses'!$E$6:$E$10000,'Main Expenses'!$B$6:$B$10000,"Amazon US",'Main Expenses'!$K$6:$K$10000,"May",'Main Expenses'!$L$6:$L$10000,$O$21) | I25: =SUMIFS('Main Expenses'!$E$6:$E$10000,'Main Expenses'!$B$6:$B$10000,"Amazon US",'Main Expenses'!$K$6:$K$10000,"Jun",'Main Expenses'!$L$6:$L$10000,$O$21) | J25: =SUMIFS('Main Expenses'!$E$6:$E$10000,'Main Expenses'!$B$6:$B$10000,"Amazon US",'Main Expenses'!$K$6:$K$10000,"Jul",'Main Expenses'!$L$6:$L$10000,$O$21) | K25: =SUMIFS('Main Expenses'!$E$6:$E$10000,'Main Expenses'!$B$6:$B$10000,"Amazon US",'Main Expenses'!$K$6:$K$10000,"Aug",'Main Expenses'!$L$6:$L$10000,$O$21) | L25: =SUMIFS('Main Expenses'!$E$6:$E$10000,'Main Expenses'!$B$6:$B$10000,"Amazon US",'Main Expenses'!$K$6:$K$10000,"Sep",'Main Expenses'!$L$6:$L$10000,$O$21) | M25: =SUMIFS('Main Expenses'!$E$6:$E$10000,'Main Expenses'!$B$6:$B$10000,"Amazon US",'Main Expenses'!$K$6:$K$10000,"Oct",'Main Expenses'!$L$6:$L$10000,$O$21) | N25: =SUMIFS('Main Expenses'!$E$6:$E$10000,'Main Expenses'!$B$6:$B$10000,"Amazon US",'Main Expenses'!$K$6:$K$10000,"Nov",'Main Expenses'!$L$6:$L$10000,$O$21) | O25: =SUMIFS('Main Expenses'!$E$6:$E$10000,'Main Expenses'!$B$6:$B$10000,"Amazon US",'Main Expenses'!$K$6:$K$10000,"Dec",'Main Expenses'!$L$6:$L$10000,$O$21) | P25: =SUM(D25:O25)
C26: Net Profit | D26: =D24+D25 | E26: =E24+E25 | F26: =F24+F25 | G26: =G24+G25 | H26: =H24+H25 | I26: =I24+I25 | J26: =J24+J25 | K26: =K24+K25 | ... O26: =O24+O25 | P26: =SUM(D26:O26)
C27: Margin % | D27: =IFERROR(D26/D24,0) | E27: =IFERROR(E26/E24,0) | F27: =IFERROR(F26/F24,0) | G27: =IFERROR(G26/G24,0) | H27: =IFERROR(H26/H24,0) | I27: =IFERROR(I26/I24,0) | J27: =IFERROR(J26/J24,0) | K27: =IFERROR(K26/K24,0) | ... P27: =IFERROR(P26/P24,0)
B28: Amazon CA | C28: Sales | D28: =SUMIFS('Sales Data'!$E$6:$E$10000,'Sales Data'!$B$6:$B$10000,"Amazon CA",'Sales Data'!$BC$6:$BC$10000,"Jan",'Sales Data'!$BD$6:$BD$10000,$O$21) | E28: =SUMIFS('Sales Data'!$E$6:$E$10000,'Sales Data'!$B$6:$B$10000,"Amazon CA",'Sales Data'!$BC$6:$BC$10000,"Feb",'Sales Data'!$BD$6:$BD$10000,$O$21) | F28: =SUMIFS('Sales Data'!$E$6:$E$10000,'Sales Data'!$B$6:$B$10000,"Amazon CA",'Sales Data'!$BC$6:$BC$10000,"Mar",'Sales Data'!$BD$6:$BD$10000,$O$21) | G28: =SUMIFS('Sales Data'!$E$6:$E$10000,'Sales Data'!$B$6:$B$10000,"Amazon CA",'Sales Data'!$BC$6:$BC$10000,"Apr",'Sales Data'!$BD$6:$BD$10000,$O$21) | H28: =SUMIFS('Sales Data'!$E$6:$E$10000,'Sales Data'!$B$6:$B$10000,"Amazon CA",'Sales Data'!$BC$6:$BC$10000,"May",'Sales Data'!$BD$6:$BD$10000,$O$21) | I28: =SUMIFS('Sales Data'!$E$6:$E$10000,'Sales Data'!$B$6:$B$10000,"Amazon CA",'Sales Data'!$BC$6:$BC$10000,"Jun",'Sales Data'!$BD$6:$BD$10000,$O$21) | J28: =SUMIFS('Sales Data'!$E$6:$E$10000,'Sales Data'!$B$6:$B$10000,"Amazon CA",'Sales Data'!$BC$6:$BC$10000,"Jul",'Sales Data'!$BD$6:$BD$10000,$O$21) | K28: =SUMIFS('Sales Data'!$E$6:$E$10000,'Sales Data'!$B$6:$B$10000,"Amazon CA",'Sales Data'!$BC$6:$BC$10000,"Aug",'Sales Data'!$BD$6:$BD$10000,$O$21) | L28: =SUMIFS('Sales Data'!$E$6:$E$10000,'Sales Data'!$B$6:$B$10000,"Amazon CA",'Sales Data'!$BC$6:$BC$10000,"Sep",'Sales Data'!$BD$6:$BD$10000,$O$21) | M28: =SUMIFS('Sales Data'!$E$6:$E$10000,'Sales Data'!$B$6:$B$10000,"Amazon CA",'Sales Data'!$BC$6:$BC$10000,"Oct",'Sales Data'!$BD$6:$BD$10000,$O$21) | N28: =SUMIFS('Sales Data'!$E$6:$E$10000,'Sales Data'!$B$6:$B$10000,"Amazon CA",'Sales Data'!$BC$6:$BC$10000,"Nov",'Sales Data'!$BD$6:$BD$10000,$O$21) | O28: =SUMIFS('Sales Data'!$E$6:$E$10000,'Sales Data'!$B$6:$B$10000,"Amazon CA",'Sales Data'!$BC$6:$BC$10000,"Dec",'Sales Data'!$BD$6:$BD$10000,$O$21) | P28: =SUM(D28:O28)
C29: Expenses | D29: =SUMIFS('Main Expenses'!$E$6:$E$10000,'Main Expenses'!$B$6:$B$10000,"Amazon CA",'Main Expenses'!$K$6:$K$10000,"Jan",'Main Expenses'!$L$6:$L$10000,$O$21) | E29: =SUMIFS('Main Expenses'!$E$6:$E$10000,'Main Expenses'!$B$6:$B$10000,"Amazon CA",'Main Expenses'!$K$6:$K$10000,"Feb",'Main Expenses'!$L$6:$L$10000,$O$21) | F29: =SUMIFS('Main Expenses'!$E$6:$E$10000,'Main Expenses'!$B$6:$B$10000,"Amazon CA",'Main Expenses'!$K$6:$K$10000,"Mar",'Main Expenses'!$L$6:$L$10000,$O$21) | G29: =SUMIFS('Main Expenses'!$E$6:$E$10000,'Main Expenses'!$B$6:$B$10000,"Amazon CA",'Main Expenses'!$K$6:$K$10000,"Apr",'Main Expenses'!$L$6:$L$10000,$O$21) | H29: =SUMIFS('Main Expenses'!$E$6:$E$10000,'Main Expenses'!$B$6:$B$10000,"Amazon CA",'Main Expenses'!$K$6:$K$10000,"May",'Main Expenses'!$L$6:$L$10000,$O$21) | I29: =SUMIFS('Main Expenses'!$E$6:$E$10000,'Main Expenses'!$B$6:$B$10000,"Amazon CA",'Main Expenses'!$K$6:$K$10000,"Jun",'Main Expenses'!$L$6:$L$10000,$O$21) | J29: =SUMIFS('Main Expenses'!$E$6:$E$10000,'Main Expenses'!$B$6:$B$10000,"Amazon CA",'Main Expenses'!$K$6:$K$10000,"Jul",'Main Expenses'!$L$6:$L$10000,$O$21) | K29: =SUMIFS('Main Expenses'!$E$6:$E$10000,'Main Expenses'!$B$6:$B$10000,"Amazon CA",'Main Expenses'!$K$6:$K$10000,"Aug",'Main Expenses'!$L$6:$L$10000,$O$21) | L29: =SUMIFS('Main Expenses'!$E$6:$E$10000,'Main Expenses'!$B$6:$B$10000,"Amazon CA",'Main Expenses'!$K$6:$K$10000,"Sep",'Main Expenses'!$L$6:$L$10000,$O$21) | M29: =SUMIFS('Main Expenses'!$E$6:$E$10000,'Main Expenses'!$B$6:$B$10000,"Amazon CA",'Main Expenses'!$K$6:$K$10000,"Oct",'Main Expenses'!$L$6:$L$10000,$O$21) | N29: =SUMIFS('Main Expenses'!$E$6:$E$10000,'Main Expenses'!$B$6:$B$10000,"Amazon CA",'Main Expenses'!$K$6:$K$10000,"Nov",'Main Expenses'!$L$6:$L$10000,$O$21) | O29: =SUMIFS('Main Expenses'!$E$6:$E$10000,'Main Expenses'!$B$6:$B$10000,"Amazon CA",'Main Expenses'!$K$6:$K$10000,"Dec",'Main Expenses'!$L$6:$L$10000,$O$21) | P29: =SUM(D29:O29)
C30: Net Profit | D30: =D28+D29 | E30: =E28+E29 | F30: =F28+F29 | G30: =G28+G29 | H30: =H28+H29 | I30: =I28+I29 | J30: =J28+J29 | K30: =K28+K29 | ... O30: =O28+O29 | P30: =SUM(D30:O30)
C31: Margin % | D31: =IFERROR(D30/D28,0) | E31: =IFERROR(E30/E28,0) | F31: =IFERROR(F30/F28,0) | G31: =IFERROR(G30/G28,0) | H31: =IFERROR(H30/H28,0) | I31: =IFERROR(I30/I28,0) | J31: =IFERROR(J30/J28,0) | K31: =IFERROR(K30/K28,0) | ... P31: =IFERROR(P30/P28,0)
B32: Amazon UK | C32: Sales | D32: =SUMIFS('Sales Data'!$E$6:$E$10000,'Sales Data'!$B$6:$B$10000,"Amazon UK",'Sales Data'!$BC$6:$BC$10000,"Jan",'Sales Data'!$BD$6:$BD$10000,$O$21) | E32: =SUMIFS('Sales Data'!$E$6:$E$10000,'Sales Data'!$B$6:$B$10000,"Amazon UK",'Sales Data'!$BC$6:$BC$10000,"Feb",'Sales Data'!$BD$6:$BD$10000,$O$21) | F32: =SUMIFS('Sales Data'!$E$6:$E$10000,'Sales Data'!$B$6:$B$10000,"Amazon UK",'Sales Data'!$BC$6:$BC$10000,"Mar",'Sales Data'!$BD$6:$BD$10000,$O$21) | G32: =SUMIFS('Sales Data'!$E$6:$E$10000,'Sales Data'!$B$6:$B$10000,"Amazon UK",'Sales Data'!$BC$6:$BC$10000,"Apr",'Sales Data'!$BD$6:$BD$10000,$O$21) | H32: =SUMIFS('Sales Data'!$E$6:$E$10000,'Sales Data'!$B$6:$B$10000,"Amazon UK",'Sales Data'!$BC$6:$BC$10000,"May",'Sales Data'!$BD$6:$BD$10000,$O$21) | I32: =SUMIFS('Sales Data'!$E$6:$E$10000,'Sales Data'!$B$6:$B$10000,"Amazon UK",'Sales Data'!$BC$6:$BC$10000,"Jun",'Sales Data'!$BD$6:$BD$10000,$O$21) | J32: =SUMIFS('Sales Data'!$E$6:$E$10000,'Sales Data'!$B$6:$B$10000,"Amazon UK",'Sales Data'!$BC$6:$BC$10000,"Jul",'Sales Data'!$BD$6:$BD$10000,$O$21) | K32: =SUMIFS('Sales Data'!$E$6:$E$10000,'Sales Data'!$B$6:$B$10000,"Amazon UK",'Sales Data'!$BC$6:$BC$10000,"Aug",'Sales Data'!$BD$6:$BD$10000,$O$21) | L32: =SUMIFS('Sales Data'!$E$6:$E$10000,'Sales Data'!$B$6:$B$10000,"Amazon UK",'Sales Data'!$BC$6:$BC$10000,"Sep",'Sales Data'!$BD$6:$BD$10000,$O$21) | M32: =SUMIFS('Sales Data'!$E$6:$E$10000,'Sales Data'!$B$6:$B$10000,"Amazon UK",'Sales Data'!$BC$6:$BC$10000,"Oct",'Sales Data'!$BD$6:$BD$10000,$O$21) | N32: =SUMIFS('Sales Data'!$E$6:$E$10000,'Sales Data'!$B$6:$B$10000,"Amazon UK",'Sales Data'!$BC$6:$BC$10000,"Nov",'Sales Data'!$BD$6:$BD$10000,$O$21) | O32: =SUMIFS('Sales Data'!$E$6:$E$10000,'Sales Data'!$B$6:$B$10000,"Amazon UK",'Sales Data'!$BC$6:$BC$10000,"Dec",'Sales Data'!$BD$6:$BD$10000,$O$21) | P32: =SUM(D32:O32)
C33: Expenses | D33: =SUMIFS('Main Expenses'!$E$6:$E$10000,'Main Expenses'!$B$6:$B$10000,"Amazon UK",'Main Expenses'!$K$6:$K$10000,"Jan",'Main Expenses'!$L$6:$L$10000,$O$21) | E33: =SUMIFS('Main Expenses'!$E$6:$E$10000,'Main Expenses'!$B$6:$B$10000,"Amazon UK",'Main Expenses'!$K$6:$K$10000,"Feb",'Main Expenses'!$L$6:$L$10000,$O$21) | F33: =SUMIFS('Main Expenses'!$E$6:$E$10000,'Main Expenses'!$B$6:$B$10000,"Amazon UK",'Main Expenses'!$K$6:$K$10000,"Mar",'Main Expenses'!$L$6:$L$10000,$O$21) | G33: =SUMIFS('Main Expenses'!$E$6:$E$10000,'Main Expenses'!$B$6:$B$10000,"Amazon UK",'Main Expenses'!$K$6:$K$10000,"Apr",'Main Expenses'!$L$6:$L$10000,$O$21) | H33: =SUMIFS('Main Expenses'!$E$6:$E$10000,'Main Expenses'!$B$6:$B$10000,"Amazon UK",'Main Expenses'!$K$6:$K$10000,"May",'Main Expenses'!$L$6:$L$10000,$O$21) | I33: =SUMIFS('Main Expenses'!$E$6:$E$10000,'Main Expenses'!$B$6:$B$10000,"Amazon UK",'Main Expenses'!$K$6:$K$10000,"Jun",'Main Expenses'!$L$6:$L$10000,$O$21) | J33: =SUMIFS('Main Expenses'!$E$6:$E$10000,'Main Expenses'!$B$6:$B$10000,"Amazon UK",'Main Expenses'!$K$6:$K$10000,"Jul",'Main Expenses'!$L$6:$L$10000,$O$21) | K33: =SUMIFS('Main Expenses'!$E$6:$E$10000,'Main Expenses'!$B$6:$B$10000,"Amazon UK",'Main Expenses'!$K$6:$K$10000,"Aug",'Main Expenses'!$L$6:$L$10000,$O$21) | L33: =SUMIFS('Main Expenses'!$E$6:$E$10000,'Main Expenses'!$B$6:$B$10000,"Amazon UK",'Main Expenses'!$K$6:$K$10000,"Sep",'Main Expenses'!$L$6:$L$10000,$O$21) | M33: =SUMIFS('Main Expenses'!$E$6:$E$10000,'Main Expenses'!$B$6:$B$10000,"Amazon UK",'Main Expenses'!$K$6:$K$10000,"Oct",'Main Expenses'!$L$6:$L$10000,$O$21) | N33: =SUMIFS('Main Expenses'!$E$6:$E$10000,'Main Expenses'!$B$6:$B$10000,"Amazon UK",'Main Expenses'!$K$6:$K$10000,"Nov",'Main Expenses'!$L$6:$L$10000,$O$21) | O33: =SUMIFS('Main Expenses'!$E$6:$E$10000,'Main Expenses'!$B$6:$B$10000,"Amazon UK",'Main Expenses'!$K$6:$K$10000,"Dec",'Main Expenses'!$L$6:$L$10000,$O$21) | P33: =SUM(D33:O33)
C34: Net Profit | D34: =D32+D33 | E34: =E32+E33 | F34: =F32+F33 | G34: =G32+G33 | H34: =H32+H33 | I34: =I32+I33 | J34: =J32+J33 | K34: =K32+K33 | ... O34: =O32+O33 | P34: =SUM(D34:O34)
C35: Margin % | D35: =IFERROR(D34/D32,0) | E35: =IFERROR(E34/E32,0) | F35: =IFERROR(F34/F32,0) | G35: =IFERROR(G34/G32,0) | H35: =IFERROR(H34/H32,0) | I35: =IFERROR(I34/I32,0) | J35: =IFERROR(J34/J32,0) | K35: =IFERROR(K34/K32,0) | ... P35: =IFERROR(P34/P32,0)
B36: TikTok Shop | C36: Sales | D36: =SUMIFS('Sales Data'!$E$6:$E$10000,'Sales Data'!$B$6:$B$10000,"Tiktok",'Sales Data'!$BC$6:$BC$10000,"Jan",'Sales Data'!$BD$6:$BD$10000,$O$21) | E36: =SUMIFS('Sales Data'!$E$6:$E$10000,'Sales Data'!$B$6:$B$10000,"Tiktok",'Sales Data'!$BC$6:$BC$10000,"Feb",'Sales Data'!$BD$6:$BD$10000,$O$21) | F36: =SUMIFS('Sales Data'!$E$6:$E$10000,'Sales Data'!$B$6:$B$10000,"Tiktok",'Sales Data'!$BC$6:$BC$10000,"Mar",'Sales Data'!$BD$6:$BD$10000,$O$21) | G36: =SUMIFS('Sales Data'!$E$6:$E$10000,'Sales Data'!$B$6:$B$10000,"Tiktok",'Sales Data'!$BC$6:$BC$10000,"Apr",'Sales Data'!$BD$6:$BD$10000,$O$21) | H36: =SUMIFS('Sales Data'!$E$6:$E$10000,'Sales Data'!$B$6:$B$10000,"Tiktok",'Sales Data'!$BC$6:$BC$10000,"May",'Sales Data'!$BD$6:$BD$10000,$O$21) | I36: =SUMIFS('Sales Data'!$E$6:$E$10000,'Sales Data'!$B$6:$B$10000,"Tiktok",'Sales Data'!$BC$6:$BC$10000,"Jun",'Sales Data'!$BD$6:$BD$10000,$O$21) | J36: =SUMIFS('Sales Data'!$E$6:$E$10000,'Sales Data'!$B$6:$B$10000,"Tiktok",'Sales Data'!$BC$6:$BC$10000,"Jul",'Sales Data'!$BD$6:$BD$10000,$O$21) | K36: =SUMIFS('Sales Data'!$E$6:$E$10000,'Sales Data'!$B$6:$B$10000,"Tiktok",'Sales Data'!$BC$6:$BC$10000,"Aug",'Sales Data'!$BD$6:$BD$10000,$O$21) | L36: =SUMIFS('Sales Data'!$E$6:$E$10000,'Sales Data'!$B$6:$B$10000,"Tiktok",'Sales Data'!$BC$6:$BC$10000,"Sep",'Sales Data'!$BD$6:$BD$10000,$O$21) | M36: =SUMIFS('Sales Data'!$E$6:$E$10000,'Sales Data'!$B$6:$B$10000,"Tiktok",'Sales Data'!$BC$6:$BC$10000,"Oct",'Sales Data'!$BD$6:$BD$10000,$O$21) | N36: =SUMIFS('Sales Data'!$E$6:$E$10000,'Sales Data'!$B$6:$B$10000,"Tiktok",'Sales Data'!$BC$6:$BC$10000,"Nov",'Sales Data'!$BD$6:$BD$10000,$O$21) | O36: =SUMIFS('Sales Data'!$E$6:$E$10000,'Sales Data'!$B$6:$B$10000,"Tiktok",'Sales Data'!$BC$6:$BC$10000,"Dec",'Sales Data'!$BD$6:$BD$10000,$O$21) | P36: =SUM(D36:O36)
C37: Expenses | D37: =SUMIFS('Main Expenses'!$E$6:$E$10000,'Main Expenses'!$B$6:$B$10000,"Tiktok",'Main Expenses'!$K$6:$K$10000,"Jan",'Main Expenses'!$L$6:$L$10000,$O$21) | E37: =SUMIFS('Main Expenses'!$E$6:$E$10000,'Main Expenses'!$B$6:$B$10000,"Tiktok",'Main Expenses'!$K$6:$K$10000,"Feb",'Main Expenses'!$L$6:$L$10000,$O$21) | F37: =SUMIFS('Main Expenses'!$E$6:$E$10000,'Main Expenses'!$B$6:$B$10000,"Tiktok",'Main Expenses'!$K$6:$K$10000,"Mar",'Main Expenses'!$L$6:$L$10000,$O$21) | G37: =SUMIFS('Main Expenses'!$E$6:$E$10000,'Main Expenses'!$B$6:$B$10000,"Tiktok",'Main Expenses'!$K$6:$K$10000,"Apr",'Main Expenses'!$L$6:$L$10000,$O$21) | H37: =SUMIFS('Main Expenses'!$E$6:$E$10000,'Main Expenses'!$B$6:$B$10000,"Tiktok",'Main Expenses'!$K$6:$K$10000,"May",'Main Expenses'!$L$6:$L$10000,$O$21) | I37: =SUMIFS('Main Expenses'!$E$6:$E$10000,'Main Expenses'!$B$6:$B$10000,"Tiktok",'Main Expenses'!$K$6:$K$10000,"Jun",'Main Expenses'!$L$6:$L$10000,$O$21) | J37: =SUMIFS('Main Expenses'!$E$6:$E$10000,'Main Expenses'!$B$6:$B$10000,"Tiktok",'Main Expenses'!$K$6:$K$10000,"Jul",'Main Expenses'!$L$6:$L$10000,$O$21) | K37: =SUMIFS('Main Expenses'!$E$6:$E$10000,'Main Expenses'!$B$6:$B$10000,"Tiktok",'Main Expenses'!$K$6:$K$10000,"Aug",'Main Expenses'!$L$6:$L$10000,$O$21) | L37: =SUMIFS('Main Expenses'!$E$6:$E$10000,'Main Expenses'!$B$6:$B$10000,"Tiktok",'Main Expenses'!$K$6:$K$10000,"Sep",'Main Expenses'!$L$6:$L$10000,$O$21) | M37: =SUMIFS('Main Expenses'!$E$6:$E$10000,'Main Expenses'!$B$6:$B$10000,"Tiktok",'Main Expenses'!$K$6:$K$10000,"Oct",'Main Expenses'!$L$6:$L$10000,$O$21) | N37: =SUMIFS('Main Expenses'!$E$6:$E$10000,'Main Expenses'!$B$6:$B$10000,"Tiktok",'Main Expenses'!$K$6:$K$10000,"Nov",'Main Expenses'!$L$6:$L$10000,$O$21) | O37: =SUMIFS('Main Expenses'!$E$6:$E$10000,'Main Expenses'!$B$6:$B$10000,"Tiktok",'Main Expenses'!$K$6:$K$10000,"Dec",'Main Expenses'!$L$6:$L$10000,$O$21) | P37: =SUM(D37:O37)
C38: Net Profit | D38: =D36+D37 | E38: =E36+E37 | F38: =F36+F37 | G38: =G36+G37 | H38: =H36+H37 | I38: =I36+I37 | J38: =J36+J37 | K38: =K36+K37 | ... O38: =O36+O37 | P38: =SUM(D38:O38)
C39: Margin % | D39: =IFERROR(D38/D36,0) | E39: =IFERROR(E38/E36,0) | F39: =IFERROR(F38/F36,0) | G39: =IFERROR(G38/G36,0) | H39: =IFERROR(H38/H36,0) | I39: =IFERROR(I38/I36,0) | J39: =IFERROR(J38/J36,0) | K39: =IFERROR(K38/K36,0) | ... P39: =IFERROR(P38/P36,0)
B40: Shopify & Faire | C40: Sales | D40: =SUMIFS('Sales Data'!$E$6:$E$10000,'Sales Data'!$B$6:$B$10000,"Shopify",'Sales Data'!$BC$6:$BC$10000,"Jan",'Sales Data'!$BD$6:$BD$10000,$O$21) | E40: =SUMIFS('Sales Data'!$E$6:$E$10000,'Sales Data'!$B$6:$B$10000,"Shopify",'Sales Data'!$BC$6:$BC$10000,"Feb",'Sales Data'!$BD$6:$BD$10000,$O$21) | F40: =SUMIFS('Sales Data'!$E$6:$E$10000,'Sales Data'!$B$6:$B$10000,"Shopify",'Sales Data'!$BC$6:$BC$10000,"Mar",'Sales Data'!$BD$6:$BD$10000,$O$21) | G40: =SUMIFS('Sales Data'!$E$6:$E$10000,'Sales Data'!$B$6:$B$10000,"Shopify",'Sales Data'!$BC$6:$BC$10000,"Apr",'Sales Data'!$BD$6:$BD$10000,$O$21) | H40: =SUMIFS('Sales Data'!$E$6:$E$10000,'Sales Data'!$B$6:$B$10000,"Shopify",'Sales Data'!$BC$6:$BC$10000,"May",'Sales Data'!$BD$6:$BD$10000,$O$21) | I40: =SUMIFS('Sales Data'!$E$6:$E$10000,'Sales Data'!$B$6:$B$10000,"Shopify",'Sales Data'!$BC$6:$BC$10000,"Jun",'Sales Data'!$BD$6:$BD$10000,$O$21) | J40: =SUMIFS('Sales Data'!$E$6:$E$10000,'Sales Data'!$B$6:$B$10000,"Shopify",'Sales Data'!$BC$6:$BC$10000,"Jul",'Sales Data'!$BD$6:$BD$10000,$O$21) | K40: =SUMIFS('Sales Data'!$E$6:$E$10000,'Sales Data'!$B$6:$B$10000,"Shopify",'Sales Data'!$BC$6:$BC$10000,"Aug",'Sales Data'!$BD$6:$BD$10000,$O$21) | L40: =SUMIFS('Sales Data'!$E$6:$E$10000,'Sales Data'!$B$6:$B$10000,"Shopify",'Sales Data'!$BC$6:$BC$10000,"Sep",'Sales Data'!$BD$6:$BD$10000,$O$21) | M40: =SUMIFS('Sales Data'!$E$6:$E$10000,'Sales Data'!$B$6:$B$10000,"Shopify",'Sales Data'!$BC$6:$BC$10000,"Oct",'Sales Data'!$BD$6:$BD$10000,$O$21) | N40: =SUMIFS('Sales Data'!$E$6:$E$10000,'Sales Data'!$B$6:$B$10000,"Shopify",'Sales Data'!$BC$6:$BC$10000,"Nov",'Sales Data'!$BD$6:$BD$10000,$O$21) | O40: =SUMIFS('Sales Data'!$E$6:$E$10000,'Sales Data'!$B$6:$B$10000,"Shopify",'Sales Data'!$BC$6:$BC$10000,"Dec",'Sales Data'!$BD$6:$BD$10000,$O$21) | P40: =SUM(D40:O40)
C41: Expenses | D41: =SUMIFS('Main Expenses'!$E$6:$E$10000,'Main Expenses'!$B$6:$B$10000,"Shopify",'Main Expenses'!$K$6:$K$10000,"Jan",'Main Expenses'!$L$6:$L$10000,$O$21) | E41: =SUMIFS('Main Expenses'!$E$6:$E$10000,'Main Expenses'!$B$6:$B$10000,"Shopify",'Main Expenses'!$K$6:$K$10000,"Feb",'Main Expenses'!$L$6:$L$10000,$O$21) | F41: =SUMIFS('Main Expenses'!$E$6:$E$10000,'Main Expenses'!$B$6:$B$10000,"Shopify",'Main Expenses'!$K$6:$K$10000,"Mar",'Main Expenses'!$L$6:$L$10000,$O$21) | G41: =SUMIFS('Main Expenses'!$E$6:$E$10000,'Main Expenses'!$B$6:$B$10000,"Shopify",'Main Expenses'!$K$6:$K$10000,"Apr",'Main Expenses'!$L$6:$L$10000,$O$21) | H41: =SUMIFS('Main Expenses'!$E$6:$E$10000,'Main Expenses'!$B$6:$B$10000,"Shopify",'Main Expenses'!$K$6:$K$10000,"May",'Main Expenses'!$L$6:$L$10000,$O$21) | I41: =SUMIFS('Main Expenses'!$E$6:$E$10000,'Main Expenses'!$B$6:$B$10000,"Shopify",'Main Expenses'!$K$6:$K$10000,"Jun",'Main Expenses'!$L$6:$L$10000,$O$21) | J41: =SUMIFS('Main Expenses'!$E$6:$E$10000,'Main Expenses'!$B$6:$B$10000,"Shopify",'Main Expenses'!$K$6:$K$10000,"Jul",'Main Expenses'!$L$6:$L$10000,$O$21) | K41: =SUMIFS('Main Expenses'!$E$6:$E$10000,'Main Expenses'!$B$6:$B$10000,"Shopify",'Main Expenses'!$K$6:$K$10000,"Aug",'Main Expenses'!$L$6:$L$10000,$O$21) | L41: =SUMIFS('Main Expenses'!$E$6:$E$10000,'Main Expenses'!$B$6:$B$10000,"Shopify",'Main Expenses'!$K$6:$K$10000,"Sep",'Main Expenses'!$L$6:$L$10000,$O$21) | M41: =SUMIFS('Main Expenses'!$E$6:$E$10000,'Main Expenses'!$B$6:$B$10000,"Shopify",'Main Expenses'!$K$6:$K$10000,"Oct",'Main Expenses'!$L$6:$L$10000,$O$21) | N41: =SUMIFS('Main Expenses'!$E$6:$E$10000,'Main Expenses'!$B$6:$B$10000,"Shopify",'Main Expenses'!$K$6:$K$10000,"Nov",'Main Expenses'!$L$6:$L$10000,$O$21) | O41: =SUMIFS('Main Expenses'!$E$6:$E$10000,'Main Expenses'!$B$6:$B$10000,"Shopify",'Main Expenses'!$K$6:$K$10000,"Dec",'Main Expenses'!$L$6:$L$10000,$O$21) | P41: =SUM(D41:O41)
C42: Net Profit | D42: =D40+D41 | E42: =E40+E41 | F42: =F40+F41 | G42: =G40+G41 | H42: =H40+H41 | I42: =I40+I41 | J42: =J40+J41 | K42: =K40+K41 | ... O42: =O40+O41 | P42: =SUM(D42:O42)
C43: Margin % | D43: =IFERROR(D42/D40,0) | E43: =IFERROR(E42/E40,0) | F43: =IFERROR(F42/F40,0) | G43: =IFERROR(G42/G40,0) | H43: =IFERROR(H42/H40,0) | I43: =IFERROR(I42/I40,0) | J43: =IFERROR(J42/J40,0) | K43: =IFERROR(K42/K40,0) | ... P43: =IFERROR(P42/P40,0)
B44: Walmart | C44: Sales | D44: =SUMIFS('Sales Data'!$E$6:$E$10000,'Sales Data'!$B$6:$B$10000,"Walmart",'Sales Data'!$BC$6:$BC$10000,"Jan",'Sales Data'!$BD$6:$BD$10000,$O$21) | E44: =SUMIFS('Sales Data'!$E$6:$E$10000,'Sales Data'!$B$6:$B$10000,"Walmart",'Sales Data'!$BC$6:$BC$10000,"Feb",'Sales Data'!$BD$6:$BD$10000,$O$21) | F44: =SUMIFS('Sales Data'!$E$6:$E$10000,'Sales Data'!$B$6:$B$10000,"Walmart",'Sales Data'!$BC$6:$BC$10000,"Mar",'Sales Data'!$BD$6:$BD$10000,$O$21) | G44: =SUMIFS('Sales Data'!$E$6:$E$10000,'Sales Data'!$B$6:$B$10000,"Walmart",'Sales Data'!$BC$6:$BC$10000,"Apr",'Sales Data'!$BD$6:$BD$10000,$O$21) | H44: =SUMIFS('Sales Data'!$E$6:$E$10000,'Sales Data'!$B$6:$B$10000,"Walmart",'Sales Data'!$BC$6:$BC$10000,"May",'Sales Data'!$BD$6:$BD$10000,$O$21) | I44: =SUMIFS('Sales Data'!$E$6:$E$10000,'Sales Data'!$B$6:$B$10000,"Walmart",'Sales Data'!$BC$6:$BC$10000,"Jun",'Sales Data'!$BD$6:$BD$10000,$O$21) | J44: =SUMIFS('Sales Data'!$E$6:$E$10000,'Sales Data'!$B$6:$B$10000,"Walmart",'Sales Data'!$BC$6:$BC$10000,"Jul",'Sales Data'!$BD$6:$BD$10000,$O$21) | K44: =SUMIFS('Sales Data'!$E$6:$E$10000,'Sales Data'!$B$6:$B$10000,"Walmart",'Sales Data'!$BC$6:$BC$10000,"Aug",'Sales Data'!$BD$6:$BD$10000,$O$21) | L44: =SUMIFS('Sales Data'!$E$6:$E$10000,'Sales Data'!$B$6:$B$10000,"Walmart",'Sales Data'!$BC$6:$BC$10000,"Sep",'Sales Data'!$BD$6:$BD$10000,$O$21) | M44: =SUMIFS('Sales Data'!$E$6:$E$10000,'Sales Data'!$B$6:$B$10000,"Walmart",'Sales Data'!$BC$6:$BC$10000,"Oct",'Sales Data'!$BD$6:$BD$10000,$O$21) | N44: =SUMIFS('Sales Data'!$E$6:$E$10000,'Sales Data'!$B$6:$B$10000,"Walmart",'Sales Data'!$BC$6:$BC$10000,"Nov",'Sales Data'!$BD$6:$BD$10000,$O$21) | O44: =SUMIFS('Sales Data'!$E$6:$E$10000,'Sales Data'!$B$6:$B$10000,"Walmart",'Sales Data'!$BC$6:$BC$10000,"Dec",'Sales Data'!$BD$6:$BD$10000,$O$21) | P44: =SUM(D44:O44)
C45: Expenses | D45: =SUMIFS('Main Expenses'!$E$6:$E$10000,'Main Expenses'!$B$6:$B$10000,"Walmart",'Main Expenses'!$K$6:$K$10000,"Jan",'Main Expenses'!$L$6:$L$10000,$O$21) | E45: =SUMIFS('Main Expenses'!$E$6:$E$10000,'Main Expenses'!$B$6:$B$10000,"Walmart",'Main Expenses'!$K$6:$K$10000,"Feb",'Main Expenses'!$L$6:$L$10000,$O$21) | F45: =SUMIFS('Main Expenses'!$E$6:$E$10000,'Main Expenses'!$B$6:$B$10000,"Walmart",'Main Expenses'!$K$6:$K$10000,"Mar",'Main Expenses'!$L$6:$L$10000,$O$21) | G45: =SUMIFS('Main Expenses'!$E$6:$E$10000,'Main Expenses'!$B$6:$B$10000,"Walmart",'Main Expenses'!$K$6:$K$10000,"Apr",'Main Expenses'!$L$6:$L$10000,$O$21) | H45: =SUMIFS('Main Expenses'!$E$6:$E$10000,'Main Expenses'!$B$6:$B$10000,"Walmart",'Main Expenses'!$K$6:$K$10000,"May",'Main Expenses'!$L$6:$L$10000,$O$21) | I45: =SUMIFS('Main Expenses'!$E$6:$E$10000,'Main Expenses'!$B$6:$B$10000,"Walmart",'Main Expenses'!$K$6:$K$10000,"Jun",'Main Expenses'!$L$6:$L$10000,$O$21) | J45: =SUMIFS('Main Expenses'!$E$6:$E$10000,'Main Expenses'!$B$6:$B$10000,"Walmart",'Main Expenses'!$K$6:$K$10000,"Jul",'Main Expenses'!$L$6:$L$10000,$O$21) | K45: =SUMIFS('Main Expenses'!$E$6:$E$10000,'Main Expenses'!$B$6:$B$10000,"Walmart",'Main Expenses'!$K$6:$K$10000,"Aug",'Main Expenses'!$L$6:$L$10000,$O$21) | L45: =SUMIFS('Main Expenses'!$E$6:$E$10000,'Main Expenses'!$B$6:$B$10000,"Walmart",'Main Expenses'!$K$6:$K$10000,"Sep",'Main Expenses'!$L$6:$L$10000,$O$21) | M45: =SUMIFS('Main Expenses'!$E$6:$E$10000,'Main Expenses'!$B$6:$B$10000,"Walmart",'Main Expenses'!$K$6:$K$10000,"Oct",'Main Expenses'!$L$6:$L$10000,$O$21) | N45: =SUMIFS('Main Expenses'!$E$6:$E$10000,'Main Expenses'!$B$6:$B$10000,"Walmart",'Main Expenses'!$K$6:$K$10000,"Nov",'Main Expenses'!$L$6:$L$10000,$O$21) | O45: =SUMIFS('Main Expenses'!$E$6:$E$10000,'Main Expenses'!$B$6:$B$10000,"Walmart",'Main Expenses'!$K$6:$K$10000,"Dec",'Main Expenses'!$L$6:$L$10000,$O$21) | P45: =SUM(D45:O45)
C46: Net Profit | D46: =D44+D45 | E46: =E44+E45 | F46: =F44+F45 | G46: =G44+G45 | H46: =H44+H45 | I46: =I44+I45 | J46: =J44+J45 | K46: =K44+K45 | ... O46: =O44+O45 | P46: =SUM(D46:O46)
C47: Margin % | D47: =IFERROR(D46/D44,0) | E47: =IFERROR(E46/E44,0) | F47: =IFERROR(F46/F44,0) | G47: =IFERROR(G46/G44,0) | H47: =IFERROR(H46/H44,0) | I47: =IFERROR(I46/I44,0) | J47: =IFERROR(J46/J44,0) | K47: =IFERROR(K46/K44,0) | ... P47: =IFERROR(P46/P44,0)

Sheet Monthly Data
B2: MONTHLY DATA · ALL SALES CHANNELS
B3: One block per month · Sales + Expenses + Net Profit + Margin per marketplace
B6: JAN 2025
B7: Date | C7: Marketplace | D7: Sales (USD) | E7: Expenses (USD) | F7: Net Profit | G7: Margin | H7: Sales %
B8: 45688 | C8: Amazon US | D8: =SUMIFS('Sales Data'!$E$6:$E$10000,'Sales Data'!$B$6:$B$10000,"Amazon US",'Sales Data'!$BC$6:$BC$10000,"Jan",'Sales Data'!$BD$6:$BD$10000,2025) | E8: =SUMIFS('Main Expenses'!$E$6:$E$10000,'Main Expenses'!$B$6:$B$10000,"Amazon US",'Main Expenses'!$K$6:$K$10000,"Jan",'Main Expenses'!$L$6:$L$10000,2025) | F8: =D8+E8 | G8: =IFERROR(F8/D8,0) | H8: =IFERROR(D8/SUMIFS('Sales Data'!$E$6:$E$10000,'Sales Data'!$BC$6:$BC$10000,"Jan",'Sales Data'!$BD$6:$BD$10000,2025),0)
C9: Amazon CA | D9: =SUMIFS('Sales Data'!$E$6:$E$10000,'Sales Data'!$B$6:$B$10000,"Amazon CA",'Sales Data'!$BC$6:$BC$10000,"Jan",'Sales Data'!$BD$6:$BD$10000,2025) | E9: =SUMIFS('Main Expenses'!$E$6:$E$10000,'Main Expenses'!$B$6:$B$10000,"Amazon CA",'Main Expenses'!$K$6:$K$10000,"Jan",'Main Expenses'!$L$6:$L$10000,2025) | F9: =D9+E9 | G9: =IFERROR(F9/D9,0) | H9: =IFERROR(D9/SUMIFS('Sales Data'!$E$6:$E$10000,'Sales Data'!$BC$6:$BC$10000,"Jan",'Sales Data'!$BD$6:$BD$10000,2025),0)
C10: Amazon UK | D10: =SUMIFS('Sales Data'!$E$6:$E$10000,'Sales Data'!$B$6:$B$10000,"Amazon UK",'Sales Data'!$BC$6:$BC$10000,"Jan",'Sales Data'!$BD$6:$BD$10000,2025) | E10: =SUMIFS('Main Expenses'!$E$6:$E$10000,'Main Expenses'!$B$6:$B$10000,"Amazon UK",'Main Expenses'!$K$6:$K$10000,"Jan",'Main Expenses'!$L$6:$L$10000,2025) | F10: =D10+E10 | G10: =IFERROR(F10/D10,0) | H10: =IFERROR(D10/SUMIFS('Sales Data'!$E$6:$E$10000,'Sales Data'!$BC$6:$BC$10000,"Jan",'Sales Data'!$BD$6:$BD$10000,2025),0)
C11: TikTok Shop | D11: =SUMIFS('Sales Data'!$E$6:$E$10000,'Sales Data'!$B$6:$B$10000,"Tiktok",'Sales Data'!$BC$6:$BC$10000,"Jan",'Sales Data'!$BD$6:$BD$10000,2025) | E11: =SUMIFS('Main Expenses'!$E$6:$E$10000,'Main Expenses'!$B$6:$B$10000,"Tiktok",'Main Expenses'!$K$6:$K$10000,"Jan",'Main Expenses'!$L$6:$L$10000,2025) | F11: =D11+E11 | G11: =IFERROR(F11/D11,0) | H11: =IFERROR(D11/SUMIFS('Sales Data'!$E$6:$E$10000,'Sales Data'!$BC$6:$BC$10000,"Jan",'Sales Data'!$BD$6:$BD$10000,2025),0)
C12: Shopify & Faire | D12: =SUMIFS('Sales Data'!$E$6:$E$10000,'Sales Data'!$B$6:$B$10000,"Shopify",'Sales Data'!$BC$6:$BC$10000,"Jan",'Sales Data'!$BD$6:$BD$10000,2025) | E12: =SUMIFS('Main Expenses'!$E$6:$E$10000,'Main Expenses'!$B$6:$B$10000,"Shopify",'Main Expenses'!$K$6:$K$10000,"Jan",'Main Expenses'!$L$6:$L$10000,2025) | F12: =D12+E12 | G12: =IFERROR(F12/D12,0) | H12: =IFERROR(D12/SUMIFS('Sales Data'!$E$6:$E$10000,'Sales Data'!$BC$6:$BC$10000,"Jan",'Sales Data'!$BD$6:$BD$10000,2025),0)
C13: Walmart | D13: =SUMIFS('Sales Data'!$E$6:$E$10000,'Sales Data'!$B$6:$B$10000,"Walmart",'Sales Data'!$BC$6:$BC$10000,"Jan",'Sales Data'!$BD$6:$BD$10000,2025) | E13: =SUMIFS('Main Expenses'!$E$6:$E$10000,'Main Expenses'!$B$6:$B$10000,"Walmart",'Main Expenses'!$K$6:$K$10000,"Jan",'Main Expenses'!$L$6:$L$10000,2025) | F13: =D13+E13 | G13: =IFERROR(F13/D13,0) | H13: =IFERROR(D13/SUMIFS('Sales Data'!$E$6:$E$10000,'Sales Data'!$BC$6:$BC$10000,"Jan",'Sales Data'!$BD$6:$BD$10000,2025),0)
B14: TOTAL: | D14: =SUM(D8:D13) | E14: =SUM(E8:E13) | F14: =SUM(F8:F13) | G14: =IFERROR(F14/D14,0) | H14: 1
B16: FEB 2025
B17: Date | C17: Marketplace | D17: Sales (USD) | E17: Expenses (USD) | F17: Net Profit | G17: Margin | H17: Sales %
B18: 45716 | C18: Amazon US | D18: =SUMIFS('Sales Data'!$E$6:$E$10000,'Sales Data'!$B$6:$B$10000,"Amazon US",'Sales Data'!$BC$6:$BC$10000,"Feb",'Sales Data'!$BD$6:$BD$10000,2025) | E18: =SUMIFS('Main Expenses'!$E$6:$E$10000,'Main Expenses'!$B$6:$B$10000,"Amazon US",'Main Expenses'!$K$6:$K$10000,"Feb",'Main Expenses'!$L$6:$L$10000,2025) | F18: =D18+E18 | G18: =IFERROR(F18/D18,0) | H18: =IFERROR(D18/SUMIFS('Sales Data'!$E$6:$E$10000,'Sales Data'!$BC$6:$BC$10000,"Feb",'Sales Data'!$BD$6:$BD$10000,2025),0)
C19: Amazon CA | D19: =SUMIFS('Sales Data'!$E$6:$E$10000,'Sales Data'!$B$6:$B$10000,"Amazon CA",'Sales Data'!$BC$6:$BC$10000,"Feb",'Sales Data'!$BD$6:$BD$10000,2025) | E19: =SUMIFS('Main Expenses'!$E$6:$E$10000,'Main Expenses'!$B$6:$B$10000,"Amazon CA",'Main Expenses'!$K$6:$K$10000,"Feb",'Main Expenses'!$L$6:$L$10000,2025) | F19: =D19+E19 | G19: =IFERROR(F19/D19,0) | H19: =IFERROR(D19/SUMIFS('Sales Data'!$E$6:$E$10000,'Sales Data'!$BC$6:$BC$10000,"Feb",'Sales Data'!$BD$6:$BD$10000,2025),0)
C20: Amazon UK | D20: =SUMIFS('Sales Data'!$E$6:$E$10000,'Sales Data'!$B$6:$B$10000,"Amazon UK",'Sales Data'!$BC$6:$BC$10000,"Feb",'Sales Data'!$BD$6:$BD$10000,2025) | E20: =SUMIFS('Main Expenses'!$E$6:$E$10000,'Main Expenses'!$B$6:$B$10000,"Amazon UK",'Main Expenses'!$K$6:$K$10000,"Feb",'Main Expenses'!$L$6:$L$10000,2025) | F20: =D20+E20 | G20: =IFERROR(F20/D20,0) | H20: =IFERROR(D20/SUMIFS('Sales Data'!$E$6:$E$10000,'Sales Data'!$BC$6:$BC$10000,"Feb",'Sales Data'!$BD$6:$BD$10000,2025),0)
C21: TikTok Shop | D21: =SUMIFS('Sales Data'!$E$6:$E$10000,'Sales Data'!$B$6:$B$10000,"Tiktok",'Sales Data'!$BC$6:$BC$10000,"Feb",'Sales Data'!$BD$6:$BD$10000,2025) | E21: =SUMIFS('Main Expenses'!$E$6:$E$10000,'Main Expenses'!$B$6:$B$10000,"Tiktok",'Main Expenses'!$K$6:$K$10000,"Feb",'Main Expenses'!$L$6:$L$10000,2025) | F21: =D21+E21 | G21: =IFERROR(F21/D21,0) | H21: =IFERROR(D21/SUMIFS('Sales Data'!$E$6:$E$10000,'Sales Data'!$BC$6:$BC$10000,"Feb",'Sales Data'!$BD$6:$BD$10000,2025),0)
C22: Shopify & Faire | D22: =SUMIFS('Sales Data'!$E$6:$E$10000,'Sales Data'!$B$6:$B$10000,"Shopify",'Sales Data'!$BC$6:$BC$10000,"Feb",'Sales Data'!$BD$6:$BD$10000,2025) | E22: =SUMIFS('Main Expenses'!$E$6:$E$10000,'Main Expenses'!$B$6:$B$10000,"Shopify",'Main Expenses'!$K$6:$K$10000,"Feb",'Main Expenses'!$L$6:$L$10000,2025) | F22: =D22+E22 | G22: =IFERROR(F22/D22,0) | H22: =IFERROR(D22/SUMIFS('Sales Data'!$E$6:$E$10000,'Sales Data'!$BC$6:$BC$10000,"Feb",'Sales Data'!$BD$6:$BD$10000,2025),0)
C23: Walmart | D23: =SUMIFS('Sales Data'!$E$6:$E$10000,'Sales Data'!$B$6:$B$10000,"Walmart",'Sales Data'!$BC$6:$BC$10000,"Feb",'Sales Data'!$BD$6:$BD$10000,2025) | E23: =SUMIFS('Main Expenses'!$E$6:$E$10000,'Main Expenses'!$B$6:$B$10000,"Walmart",'Main Expenses'!$K$6:$K$10000,"Feb",'Main Expenses'!$L$6:$L$10000,2025) | F23: =D23+E23 | G23: =IFERROR(F23/D23,0) | H23: =IFERROR(D23/SUMIFS('Sales Data'!$E$6:$E$10000,'Sales Data'!$BC$6:$BC$10000,"Feb",'Sales Data'!$BD$6:$BD$10000,2025),0)
B24: TOTAL: | D24: =SUM(D18:D23) | E24: =SUM(E18:E23) | F24: =SUM(F18:F23) | G24: =IFERROR(F24/D24,0) | H24: 1
B26: MAR 2025
B27: Date | C27: Marketplace | D27: Sales (USD) | E27: Expenses (USD) | F27: Net Profit | G27: Margin | H27: Sales %
B28: 45747 | C28: Amazon US | D28: =SUMIFS('Sales Data'!$E$6:$E$10000,'Sales Data'!$B$6:$B$10000,"Amazon US",'Sales Data'!$BC$6:$BC$10000,"Mar",'Sales Data'!$BD$6:$BD$10000,2025) | E28: =SUMIFS('Main Expenses'!$E$6:$E$10000,'Main Expenses'!$B$6:$B$10000,"Amazon US",'Main Expenses'!$K$6:$K$10000,"Mar",'Main Expenses'!$L$6:$L$10000,2025) | F28: =D28+E28 | G28: =IFERROR(F28/D28,0) | H28: =IFERROR(D28/SUMIFS('Sales Data'!$E$6:$E$10000,'Sales Data'!$BC$6:$BC$10000,"Mar",'Sales Data'!$BD$6:$BD$10000,2025),0)
C29: Amazon CA | D29: =SUMIFS('Sales Data'!$E$6:$E$10000,'Sales Data'!$B$6:$B$10000,"Amazon CA",'Sales Data'!$BC$6:$BC$10000,"Mar",'Sales Data'!$BD$6:$BD$10000,2025) | E29: =SUMIFS('Main Expenses'!$E$6:$E$10000,'Main Expenses'!$B$6:$B$10000,"Amazon CA",'Main Expenses'!$K$6:$K$10000,"Mar",'Main Expenses'!$L$6:$L$10000,2025) | F29: =D29+E29 | G29: =IFERROR(F29/D29,0) | H29: =IFERROR(D29/SUMIFS('Sales Data'!$E$6:$E$10000,'Sales Data'!$BC$6:$BC$10000,"Mar",'Sales Data'!$BD$6:$BD$10000,2025),0)
C30: Amazon UK | D30: =SUMIFS('Sales Data'!$E$6:$E$10000,'Sales Data'!$B$6:$B$10000,"Amazon UK",'Sales Data'!$BC$6:$BC$10000,"Mar",'Sales Data'!$BD$6:$BD$10000,2025) | E30: =SUMIFS('Main Expenses'!$E$6:$E$10000,'Main Expenses'!$B$6:$B$10000,"Amazon UK",'Main Expenses'!$K$6:$K$10000,"Mar",'Main Expenses'!$L$6:$L$10000,2025) | F30: =D30+E30 | G30: =IFERROR(F30/D30,0) | H30: =IFERROR(D30/SUMIFS('Sales Data'!$E$6:$E$10000,'Sales Data'!$BC$6:$BC$10000,"Mar",'Sales Data'!$BD$6:$BD$10000,2025),0)
C31: TikTok Shop | D31: =SUMIFS('Sales Data'!$E$6:$E$10000,'Sales Data'!$B$6:$B$10000,"Tiktok",'Sales Data'!$BC$6:$BC$10000,"Mar",'Sales Data'!$BD$6:$BD$10000,2025) | E31: =SUMIFS('Main Expenses'!$E$6:$E$10000,'Main Expenses'!$B$6:$B$10000,"Tiktok",'Main Expenses'!$K$6:$K$10000,"Mar",'Main Expenses'!$L$6:$L$10000,2025) | F31: =D31+E31 | G31: =IFERROR(F31/D31,0) | H31: =IFERROR(D31/SUMIFS('Sales Data'!$E$6:$E$10000,'Sales Data'!$BC$6:$BC$10000,"Mar",'Sales Data'!$BD$6:$BD$10000,2025),0)
C32: Shopify & Faire | D32: =SUMIFS('Sales Data'!$E$6:$E$10000,'Sales Data'!$B$6:$B$10000,"Shopify",'Sales Data'!$BC$6:$BC$10000,"Mar",'Sales Data'!$BD$6:$BD$10000,2025) | E32: =SUMIFS('Main Expenses'!$E$6:$E$10000,'Main Expenses'!$B$6:$B$10000,"Shopify",'Main Expenses'!$K$6:$K$10000,"Mar",'Main Expenses'!$L$6:$L$10000,2025) | F32: =D32+E32 | G32: =IFERROR(F32/D32,0) | H32: =IFERROR(D32/SUMIFS('Sales Data'!$E$6:$E$10000,'Sales Data'!$BC$6:$BC$10000,"Mar",'Sales Data'!$BD$6:$BD$10000,2025),0)
C33: Walmart | D33: =SUMIFS('Sales Data'!$E$6:$E$10000,'Sales Data'!$B$6:$B$10000,"Walmart",'Sales Data'!$BC$6:$BC$10000,"Mar",'Sales Data'!$BD$6:$BD$10000,2025) | E33: =SUMIFS('Main Expenses'!$E$6:$E$10000,'Main Expenses'!$B$6:$B$10000,"Walmart",'Main Expenses'!$K$6:$K$10000,"Mar",'Main Expenses'!$L$6:$L$10000,2025) | F33: =D33+E33 | G33: =IFERROR(F33/D33,0) | H33: =IFERROR(D33/SUMIFS('Sales Data'!$E$6:$E$10000,'Sales Data'!$BC$6:$BC$10000,"Mar",'Sales Data'!$BD$6:$BD$10000,2025),0)
B34: TOTAL: | D34: =SUM(D28:D33) | E34: =SUM(E28:E33) | F34: =SUM(F28:F33) | G34: =IFERROR(F34/D34,0) | H34: 1
B36: APR 2025
B37: Date | C37: Marketplace | D37: Sales (USD) | E37: Expenses (USD) | F37: Net Profit | G37: Margin | H37: Sales %
B38: 45777 | C38: Amazon US | D38: =SUMIFS('Sales Data'!$E$6:$E$10000,'Sales Data'!$B$6:$B$10000,"Amazon US",'Sales Data'!$BC$6:$BC$10000,"Apr",'Sales Data'!$BD$6:$BD$10000,2025) | E38: =SUMIFS('Main Expenses'!$E$6:$E$10000,'Main Expenses'!$B$6:$B$10000,"Amazon US",'Main Expenses'!$K$6:$K$10000,"Apr",'Main Expenses'!$L$6:$L$10000,2025) | F38: =D38+E38 | G38: =IFERROR(F38/D38,0) | H38: =IFERROR(D38/SUMIFS('Sales Data'!$E$6:$E$10000,'Sales Data'!$BC$6:$BC$10000,"Apr",'Sales Data'!$BD$6:$BD$10000,2025),0)
C39: Amazon CA | D39: =SUMIFS('Sales Data'!$E$6:$E$10000,'Sales Data'!$B$6:$B$10000,"Amazon CA",'Sales Data'!$BC$6:$BC$10000,"Apr",'Sales Data'!$BD$6:$BD$10000,2025) | E39: =SUMIFS('Main Expenses'!$E$6:$E$10000,'Main Expenses'!$B$6:$B$10000,"Amazon CA",'Main Expenses'!$K$6:$K$10000,"Apr",'Main Expenses'!$L$6:$L$10000,2025) | F39: =D39+E39 | G39: =IFERROR(F39/D39,0) | H39: =IFERROR(D39/SUMIFS('Sales Data'!$E$6:$E$10000,'Sales Data'!$BC$6:$BC$10000,"Apr",'Sales Data'!$BD$6:$BD$10000,2025),0)
C40: Amazon UK | D40: =SUMIFS('Sales Data'!$E$6:$E$10000,'Sales Data'!$B$6:$B$10000,"Amazon UK",'Sales Data'!$BC$6:$BC$10000,"Apr",'Sales Data'!$BD$6:$BD$10000,2025) | E40: =SUMIFS('Main Expenses'!$E$6:$E$10000,'Main Expenses'!$B$6:$B$10000,"Amazon UK",'Main Expenses'!$K$6:$K$10000,"Apr",'Main Expenses'!$L$6:$L$10000,2025) | F40: =D40+E40 | G40: =IFERROR(F40/D40,0) | H40: =IFERROR(D40/SUMIFS('Sales Data'!$E$6:$E$10000,'Sales Data'!$BC$6:$BC$10000,"Apr",'Sales Data'!$BD$6:$BD$10000,2025),0)
C41: TikTok Shop | D41: =SUMIFS('Sales Data'!$E$6:$E$10000,'Sales Data'!$B$6:$B$10000,"Tiktok",'Sales Data'!$BC$6:$BC$10000,"Apr",'Sales Data'!$BD$6:$BD$10000,2025) | E41: =SUMIFS('Main Expenses'!$E$6:$E$10000,'Main Expenses'!$B$6:$B$10000,"Tiktok",'Main Expenses'!$K$6:$K$10000,"Apr",'Main Expenses'!$L$6:$L$10000,2025) | F41: =D41+E41 | G41: =IFERROR(F41/D41,0) | H41: =IFERROR(D41/SUMIFS('Sales Data'!$E$6:$E$10000,'Sales Data'!$BC$6:$BC$10000,"Apr",'Sales Data'!$BD$6:$BD$10000,2025),0)
C42: Shopify & Faire | D42: =SUMIFS('Sales Data'!$E$6:$E$10000,'Sales Data'!$B$6:$B$10000,"Shopify",'Sales Data'!$BC$6:$BC$10000,"Apr",'Sales Data'!$BD$6:$BD$10000,2025) | E42: =SUMIFS('Main Expenses'!$E$6:$E$10000,'Main Expenses'!$B$6:$B$10000,"Shopify",'Main Expenses'!$K$6:$K$10000,"Apr",'Main Expenses'!$L$6:$L$10000,2025) | F42: =D42+E42 | G42: =IFERROR(F42/D42,0) | H42: =IFERROR(D42/SUMIFS('Sales Data'!$E$6:$E$10000,'Sales Data'!$BC$6:$BC$10000,"Apr",'Sales Data'!$BD$6:$BD$10000,2025),0)
C43: Walmart | D43: =SUMIFS('Sales Data'!$E$6:$E$10000,'Sales Data'!$B$6:$B$10000,"Walmart",'Sales Data'!$BC$6:$BC$10000,"Apr",'Sales Data'!$BD$6:$BD$10000,2025) | E43: =SUMIFS('Main Expenses'!$E$6:$E$10000,'Main Expenses'!$B$6:$B$10000,"Walmart",'Main Expenses'!$K$6:$K$10000,"Apr",'Main Expenses'!$L$6:$L$10000,2025) | F43: =D43+E43 | G43: =IFERROR(F43/D43,0) | H43: =IFERROR(D43/SUMIFS('Sales Data'!$E$6:$E$10000,'Sales Data'!$BC$6:$BC$10000,"Apr",'Sales Data'!$BD$6:$BD$10000,2025),0)
B44: TOTAL: | D44: =SUM(D38:D43) | E44: =SUM(E38:E43) | F44: =SUM(F38:F43) | G44: =IFERROR(F44/D44,0) | H44: 1
B46: MAY 2025
B47: Date | C47: Marketplace | D47: Sales (USD) | E47: Expenses (USD) | F47: Net Profit | G47: Margin | H47: Sales %
...

Sheet Amazon Dashboard
B2: AMAZON DASHBOARD
B3: Click the + symbol on the left margin to expand sub-categories · all KPIs update live via SUMIFS formulas.
B6: MONTH | C6: YEAR | D6: MARKETPLACE | E6: CATEGORY
B7: Mar | C7: 2026 | D7: Amazon US | E7: All Categories
B9: KEY METRICS
B11: SALES | D11: =SUMIFS('Sales Data'!$E$6:$E$10000,'Sales Data'!$B$6:$B$10000,$D$7,'Sales Data'!$BC$6:$BC$10000,$B$7,'Sales Data'!$BD$6:$BD$10000,$C$7)
B12: EXPENSES | D12: =SUMIFS('Main Expenses'!$E$6:$E$10000,'Main Expenses'!$B$6:$B$10000,$D$7,'Main Expenses'!$K$6:$K$10000,$B$7,'Main Expenses'!$L$6:$L$10000,$C$7)
B13: UNIT SALES | D13: =SUMIFS('Sales Data'!$G$6:$G$10000,'Sales Data'!$B$6:$B$10000,$D$7,'Sales Data'!$BC$6:$BC$10000,$B$7,'Sales Data'!$BD$6:$BD$10000,$C$7)
B14: VAT | D14: =SUMIFS('Sales Data'!$J$6:$J$10000,'Sales Data'!$B$6:$B$10000,$D$7,'Sales Data'!$BC$6:$BC$10000,$B$7,'Sales Data'!$BD$6:$BD$10000,$C$7)
B15: NET PROFIT | D15: =SUMIFS('Sales Data'!$L$6:$L$10000,'Sales Data'!$B$6:$B$10000,$D$7,'Sales Data'!$BC$6:$BC$10000,$B$7,'Sales Data'!$BD$6:$BD$10000,$C$7)
B16: TACOS | D16: =SUMIFS('Sales Data'!$M$6:$M$10000,'Sales Data'!$B$6:$B$10000,$D$7,'Sales Data'!$BC$6:$BC$10000,$B$7,'Sales Data'!$BD$6:$BD$10000,$C$7)
B17: % REFUNDS | D17: =SUMIFS('Sales Data'!$N$6:$N$10000,'Sales Data'!$B$6:$B$10000,$D$7,'Sales Data'!$BC$6:$BC$10000,$B$7,'Sales Data'!$BD$6:$BD$10000,$C$7)
B18: SELLABLE RETURNS % | D18: =SUMIFS('Sales Data'!$O$6:$O$10000,'Sales Data'!$B$6:$B$10000,$D$7,'Sales Data'!$BC$6:$BC$10000,$B$7,'Sales Data'!$BD$6:$BD$10000,$C$7)
B19: MARGIN | D19: =SUMIFS('Sales Data'!$P$6:$P$10000,'Sales Data'!$B$6:$B$10000,$D$7,'Sales Data'!$BC$6:$BC$10000,$B$7,'Sales Data'!$BD$6:$BD$10000,$C$7)
B20: ROI | D20: =SUMIFS('Sales Data'!$Q$6:$Q$10000,'Sales Data'!$B$6:$B$10000,$D$7,'Sales Data'!$BC$6:$BC$10000,$B$7,'Sales Data'!$BD$6:$BD$10000,$C$7)
B23: MONTHLY TREND | I23: Trend Year: | J23: 2026
B25: METRIC | C25: Jan | D25: Feb | E25: Mar | F25: Apr | G25: May | H25: Jun | I25: Jul | J25: Aug | K25: Sep | L25: Oct | M25: Nov | N25: Dec | O25: YEAR TOTAL
B26: Sales (USD) | C26: =SUMIFS('Sales Data'!$E$6:$E$10000,'Sales Data'!$B$6:$B$10000,$D$7,'Sales Data'!$BC$6:$BC$10000,"Jan",'Sales Data'!$BD$6:$BD$10000,$J$23) | D26: =SUMIFS('Sales Data'!$E$6:$E$10000,'Sales Data'!$B$6:$B$10000,$D$7,'Sales Data'!$BC$6:$BC$10000,"Feb",'Sales Data'!$BD$6:$BD$10000,$J$23) | E26: =SUMIFS('Sales Data'!$E$6:$E$10000,'Sales Data'!$B$6:$B$10000,$D$7,'Sales Data'!$BC$6:$BC$10000,"Mar",'Sales Data'!$BD$6:$BD$10000,$J$23) | F26: =SUMIFS('Sales Data'!$E$6:$E$10000,'Sales Data'!$B$6:$B$10000,$D$7,'Sales Data'!$BC$6:$BC$10000,"Apr",'Sales Data'!$BD$6:$BD$10000,$J$23) | G26: =SUMIFS('Sales Data'!$E$6:$E$10000,'Sales Data'!$B$6:$B$10000,$D$7,'Sales Data'!$BC$6:$BC$10000,"May",'Sales Data'!$BD$6:$BD$10000,$J$23) | H26: =SUMIFS('Sales Data'!$E$6:$E$10000,'Sales Data'!$B$6:$B$10000,$D$7,'Sales Data'!$BC$6:$BC$10000,"Jun",'Sales Data'!$BD$6:$BD$10000,$J$23) | I26: =SUMIFS('Sales Data'!$E$6:$E$10000,'Sales Data'!$B$6:$B$10000,$D$7,'Sales Data'!$BC$6:$BC$10000,"Jul",'Sales Data'!$BD$6:$BD$10000,$J$23) | J26: =SUMIFS('Sales Data'!$E$6:$E$10000,'Sales Data'!$B$6:$B$10000,$D$7,'Sales Data'!$BC$6:$BC$10000,"Aug",'Sales Data'!$BD$6:$BD$10000,$J$23) | K26: =SUMIFS('Sales Data'!$E$6:$E$10000,'Sales Data'!$B$6:$B$10000,$D$7,'Sales Data'!$BC$6:$BC$10000,"Sep",'Sales Data'!$BD$6:$BD$10000,$J$23) | L26: =SUMIFS('Sales Data'!$E$6:$E$10000,'Sales Data'!$B$6:$B$10000,$D$7,'Sales Data'!$BC$6:$BC$10000,"Oct",'Sales Data'!$BD$6:$BD$10000,$J$23) | M26: =SUMIFS('Sales Data'!$E$6:$E$10000,'Sales Data'!$B$6:$B$10000,$D$7,'Sales Data'!$BC$6:$BC$10000,"Nov",'Sales Data'!$BD$6:$BD$10000,$J$23) | N26: =SUMIFS('Sales Data'!$E$6:$E$10000,'Sales Data'!$B$6:$B$10000,$D$7,'Sales Data'!$BC$6:$BC$10000,"Dec",'Sales Data'!$BD$6:$BD$10000,$J$23) | O26: =SUM(C26:N26)
B27: Units | C27: =SUMIFS('Sales Data'!$G$6:$G$10000,'Sales Data'!$B$6:$B$10000,$D$7,'Sales Data'!$BC$6:$BC$10000,"Jan",'Sales Data'!$BD$6:$BD$10000,$J$23) | D27: =SUMIFS('Sales Data'!$G$6:$G$10000,'Sales Data'!$B$6:$B$10000,$D$7,'Sales Data'!$BC$6:$BC$10000,"Feb",'Sales Data'!$BD$6:$BD$10000,$J$23) | E27: =SUMIFS('Sales Data'!$G$6:$G$10000,'Sales Data'!$B$6:$B$10000,$D$7,'Sales Data'!$BC$6:$BC$10000,"Mar",'Sales Data'!$BD$6:$BD$10000,$J$23) | F27: =SUMIFS('Sales Data'!$G$6:$G$10000,'Sales Data'!$B$6:$B$10000,$D$7,'Sales Data'!$BC$6:$BC$10000,"Apr",'Sales Data'!$BD$6:$BD$10000,$J$23) | G27: =SUMIFS('Sales Data'!$G$6:$G$10000,'Sales Data'!$B$6:$B$10000,$D$7,'Sales Data'!$BC$6:$BC$10000,"May",'Sales Data'!$BD$6:$BD$10000,$J$23) | H27: =SUMIFS('Sales Data'!$G$6:$G$10000,'Sales Data'!$B$6:$B$10000,$D$7,'Sales Data'!$BC$6:$BC$10000,"Jun",'Sales Data'!$BD$6:$BD$10000,$J$23) | I27: =SUMIFS('Sales Data'!$G$6:$G$10000,'Sales Data'!$B$6:$B$10000,$D$7,'Sales Data'!$BC$6:$BC$10000,"Jul",'Sales Data'!$BD$6:$BD$10000,$J$23) | J27: =SUMIFS('Sales Data'!$G$6:$G$10000,'Sales Data'!$B$6:$B$10000,$D$7,'Sales Data'!$BC$6:$BC$10000,"Aug",'Sales Data'!$BD$6:$BD$10000,$J$23) | K27: =SUMIFS('Sales Data'!$G$6:$G$10000,'Sales Data'!$B$6:$B$10000,$D$7,'Sales Data'!$BC$6:$BC$10000,"Sep",'Sales Data'!$BD$6:$BD$10000,$J$23) | L27: =SUMIFS('Sales Data'!$G$6:$G$10000,'Sales Data'!$B$6:$B$10000,$D$7,'Sales Data'!$BC$6:$BC$10000,"Oct",'Sales Data'!$BD$6:$BD$10000,$J$23) | M27: =SUMIFS('Sales Data'!$G$6:$G$10000,'Sales Data'!$B$6:$B$10000,$D$7,'Sales Data'!$BC$6:$BC$10000,"Nov",'Sales Data'!$BD$6:$BD$10000,$J$23) | N27: =SUMIFS('Sales Data'!$G$6:$G$10000,'Sales Data'!$B$6:$B$10000,$D$7,'Sales Data'!$BC$6:$BC$10000,"Dec",'Sales Data'!$BD$6:$BD$10000,$J$23) | O27: =SUM(C27:N27)
B28: Net Profit | C28: =SUMIFS('Sales Data'!$L$6:$L$10000,'Sales Data'!$B$6:$B$10000,$D$7,'Sales Data'!$BC$6:$BC$10000,"Jan",'Sales Data'!$BD$6:$BD$10000,$J$23) | D28: =SUMIFS('Sales Data'!$L$6:$L$10000,'Sales Data'!$B$6:$B$10000,$D$7,'Sales Data'!$BC$6:$BC$10000,"Feb",'Sales Data'!$BD$6:$BD$10000,$J$23) | E28: =SUMIFS('Sales Data'!$L$6:$L$10000,'Sales Data'!$B$6:$B$10000,$D$7,'Sales Data'!$BC$6:$BC$10000,"Mar",'Sales Data'!$BD$6:$BD$10000,$J$23) | F28: =SUMIFS('Sales Data'!$L$6:$L$10000,'Sales Data'!$B$6:$B$10000,$D$7,'Sales Data'!$BC$6:$BC$10000,"Apr",'Sales Data'!$BD$6:$BD$10000,$J$23) | G28: =SUMIFS('Sales Data'!$L$6:$L$10000,'Sales Data'!$B$6:$B$10000,$D$7,'Sales Data'!$BC$6:$BC$10000,"May",'Sales Data'!$BD$6:$BD$10000,$J$23) | H28: =SUMIFS('Sales Data'!$L$6:$L$10000,'Sales Data'!$B$6:$B$10000,$D$7,'Sales Data'!$BC$6:$BC$10000,"Jun",'Sales Data'!$BD$6:$BD$10000,$J$23) | I28: =SUMIFS('Sales Data'!$L$6:$L$10000,'Sales Data'!$B$6:$B$10000,$D$7,'Sales Data'!$BC$6:$BC$10000,"Jul",'Sales Data'!$BD$6:$BD$10000,$J$23) | J28: =SUMIFS('Sales Data'!$L$6:$L$10000,'Sales Data'!$B$6:$B$10000,$D$7,'Sales Data'!$BC$6:$BC$10000,"Aug",'Sales Data'!$BD$6:$BD$10000,$J$23) | K28: =SUMIFS('Sales Data'!$L$6:$L$10000,'Sales Data'!$B$6:$B$10000,$D$7,'Sales Data'!$BC$6:$BC$10000,"Sep",'Sales Data'!$BD$6:$BD$10000,$J$23) | L28: =SUMIFS('Sales Data'!$L$6:$L$10000,'Sales Data'!$B$6:$B$10000,$D$7,'Sales Data'!$BC$6:$BC$10000,"Oct",'Sales Data'!$BD$6:$BD$10000,$J$23) | M28: =SUMIFS('Sales Data'!$L$6:$L$10000,'Sales Data'!$B$6:$B$10000,$D$7,'Sales Data'!$BC$6:$BC$10000,"Nov",'Sales Data'!$BD$6:$BD$10000,$J$23) | N28: =SUMIFS('Sales Data'!$L$6:$L$10000,'Sales Data'!$B$6:$B$10000,$D$7,'Sales Data'!$BC$6:$BC$10000,"Dec",'Sales Data'!$BD$6:$BD$10000,$J$23) | O28: =SUM(C28:N28)
B29: TACOS | C29: =SUMIFS('Sales Data'!$M$6:$M$10000,'Sales Data'!$B$6:$B$10000,$D$7,'Sales Data'!$BC$6:$BC$10000,"Jan",'Sales Data'!$BD$6:$BD$10000,$J$23) | D29: =SUMIFS('Sales Data'!$M$6:$M$10000,'Sales Data'!$B$6:$B$10000,$D$7,'Sales Data'!$BC$6:$BC$10000,"Feb",'Sales Data'!$BD$6:$BD$10000,$J$23) | E29: =SUMIFS('Sales Data'!$M$6:$M$10000,'Sales Data'!$B$6:$B$10000,$D$7,'Sales Data'!$BC$6:$BC$10000,"Mar",'Sales Data'!$BD$6:$BD$10000,$J$23) | F29: =SUMIFS('Sales Data'!$M$6:$M$10000,'Sales Data'!$B$6:$B$10000,$D$7,'Sales Data'!$BC$6:$BC$10000,"Apr",'Sales Data'!$BD$6:$BD$10000,$J$23) | G29: =SUMIFS('Sales Data'!$M$6:$M$10000,'Sales Data'!$B$6:$B$10000,$D$7,'Sales Data'!$BC$6:$BC$10000,"May",'Sales Data'!$BD$6:$BD$10000,$J$23) | H29: =SUMIFS('Sales Data'!$M$6:$M$10000,'Sales Data'!$B$6:$B$10000,$D$7,'Sales Data'!$BC$6:$BC$10000,"Jun",'Sales Data'!$BD$6:$BD$10000,$J$23) | I29: =SUMIFS('Sales Data'!$M$6:$M$10000,'Sales Data'!$B$6:$B$10000,$D$7,'Sales Data'!$BC$6:$BC$10000,"Jul",'Sales Data'!$BD$6:$BD$10000,$J$23) | J29: =SUMIFS('Sales Data'!$M$6:$M$10000,'Sales Data'!$B$6:$B$10000,$D$7,'Sales Data'!$BC$6:$BC$10000,"Aug",'Sales Data'!$BD$6:$BD$10000,$J$23) | K29: =SUMIFS('Sales Data'!$M$6:$M$10000,'Sales Data'!$B$6:$B$10000,$D$7,'Sales Data'!$BC$6:$BC$10000,"Sep",'Sales Data'!$BD$6:$BD$10000,$J$23) | L29: =SUMIFS('Sales Data'!$M$6:$M$10000,'Sales Data'!$B$6:$B$10000,$D$7,'Sales Data'!$BC$6:$BC$10000,"Oct",'Sales Data'!$BD$6:$BD$10000,$J$23) | M29: =SUMIFS('Sales Data'!$M$6:$M$10000,'Sales Data'!$B$6:$B$10000,$D$7,'Sales Data'!$BC$6:$BC$10000,"Nov",'Sales Data'!$BD$6:$BD$10000,$J$23) | N29: =SUMIFS('Sales Data'!$M$6:$M$10000,'Sales Data'!$B$6:$B$10000,$D$7,'Sales Data'!$BC$6:$BC$10000,"Dec",'Sales Data'!$BD$6:$BD$10000,$J$23) | O29: =IFERROR(AVERAGE(C29:N29),0)
B30: Margin | C30: =SUMIFS('Sales Data'!$P$6:$P$10000,'Sales Data'!$B$6:$B$10000,$D$7,'Sales Data'!$BC$6:$BC$10000,"Jan",'Sales Data'!$BD$6:$BD$10000,$J$23) | D30: =SUMIFS('Sales Data'!$P$6:$P$10000,'Sales Data'!$B$6:$B$10000,$D$7,'Sales Data'!$BC$6:$BC$10000,"Feb",'Sales Data'!$BD$6:$BD$10000,$J$23) | E30: =SUMIFS('Sales Data'!$P$6:$P$10000,'Sales Data'!$B$6:$B$10000,$D$7,'Sales Data'!$BC$6:$BC$10000,"Mar",'Sales Data'!$BD$6:$BD$10000,$J$23) | F30: =SUMIFS('Sales Data'!$P$6:$P$10000,'Sales Data'!$B$6:$B$10000,$D$7,'Sales Data'!$BC$6:$BC$10000,"Apr",'Sales Data'!$BD$6:$BD$10000,$J$23) | G30: =SUMIFS('Sales Data'!$P$6:$P$10000,'Sales Data'!$B$6:$B$10000,$D$7,'Sales Data'!$BC$6:$BC$10000,"May",'Sales Data'!$BD$6:$BD$10000,$J$23) | H30: =SUMIFS('Sales Data'!$P$6:$P$10000,'Sales Data'!$B$6:$B$10000,$D$7,'Sales Data'!$BC$6:$BC$10000,"Jun",'Sales Data'!$BD$6:$BD$10000,$J$23) | I30: =SUMIFS('Sales Data'!$P$6:$P$10000,'Sales Data'!$B$6:$B$10000,$D$7,'Sales Data'!$BC$6:$BC$10000,"Jul",'Sales Data'!$BD$6:$BD$10000,$J$23) | J30: =SUMIFS('Sales Data'!$P$6:$P$10000,'Sales Data'!$B$6:$B$10000,$D$7,'Sales Data'!$BC$6:$BC$10000,"Aug",'Sales Data'!$BD$6:$BD$10000,$J$23) | K30: =SUMIFS('Sales Data'!$P$6:$P$10000,'Sales Data'!$B$6:$B$10000,$D$7,'Sales Data'!$BC$6:$BC$10000,"Sep",'Sales Data'!$BD$6:$BD$10000,$J$23) | L30: =SUMIFS('Sales Data'!$P$6:$P$10000,'Sales Data'!$B$6:$B$10000,$D$7,'Sales Data'!$BC$6:$BC$10000,"Oct",'Sales Data'!$BD$6:$BD$10000,$J$23) | M30: =SUMIFS('Sales Data'!$P$6:$P$10000,'Sales Data'!$B$6:$B$10000,$D$7,'Sales Data'!$BC$6:$BC$10000,"Nov",'Sales Data'!$BD$6:$BD$10000,$J$23) | N30: =SUMIFS('Sales Data'!$P$6:$P$10000,'Sales Data'!$B$6:$B$10000,$D$7,'Sales Data'!$BC$6:$BC$10000,"Dec",'Sales Data'!$BD$6:$BD$10000,$J$23) | O30: =IFERROR(AVERAGE(C30:N30),0)
B33: EXPENSE BREAKDOWN · MAIN & SUB CATEGORY | J33: SALES BREAKDOWN · SUB-CATEGORY
B34: CATEGORY | C34: AMOUNT | D34: % OF EXPENSES | J34: SUB CATEGORY | K34: SALES AMOUNT | L34: % OF SALES
B35: Promo | C35: =IFERROR(SUMIFS('Main Expenses'!$E$6:$E$10000,'Main Expenses'!$B$6:$B$10000,$D$7,'Main Expenses'!$D$6:$D$10000,"Promo",'Main Expenses'!$K$6:$K$10000,$B$7,'Main Expenses'!$L$6:$L$10000,$C$7),0) | D35: =IFERROR(C35/SUMIFS('Main Expenses'!$E$6:$E$10000,'Main Expenses'!$B$6:$B$10000,$D$7,'Main Expenses'!$K$6:$K$10000,$B$7,'Main Expenses'!$L$6:$L$10000,$C$7),0) | J35: Organic | K35: =IFERROR(SUMIFS('Sales Data'!$E$6:$E$10000,'Sales Data'!$B$6:$B$10000,$D$7,'Sales Data'!$D$6:$D$10000,"Organic",'Sales Data'!$BC$6:$BC$10000,$B$7,'Sales Data'!$BD$6:$BD$10000,$C$7),0) | L35: =IFERROR(K35/SUMIFS('Sales Data'!$E$6:$E$10000,'Sales Data'!$B$6:$B$10000,$D$7,'Sales Data'!$BC$6:$BC$10000,$B$7,'Sales Data'!$BD$6:$BD$10000,$C$7),0)
B36: Advertising cost | C36: =IFERROR(SUMIFS('Main Expenses'!$E$6:$E$10000,'Main Expenses'!$B$6:$B$10000,$D$7,'Main Expenses'!$D$6:$D$10000,"Advertising cost",'Main Expenses'!$K$6:$K$10000,$B$7,'Main Expenses'!$L$6:$L$10000,$C$7),0) | D36: =IFERROR(C36/SUMIFS('Main Expenses'!$E$6:$E$10000,'Main Expenses'!$B$6:$B$10000,$D$7,'Main Expenses'!$K$6:$K$10000,$B$7,'Main Expenses'!$L$6:$L$10000,$C$7),0) | J36: Sponsored Products (same day) | K36: =IFERROR(SUMIFS('Sales Data'!$E$6:$E$10000,'Sales Data'!$B$6:$B$10000,$D$7,'Sales Data'!$D$6:$D$10000,"Sponsored Products (same day)",'Sales Data'!$BC$6:$BC$10000,$B$7,'Sales Data'!$BD$6:$BD$10000,$C$7),0) | L36: =IFERROR(K36/SUMIFS('Sales Data'!$E$6:$E$10000,'Sales Data'!$B$6:$B$10000,$D$7,'Sales Data'!$BC$6:$BC$10000,$B$7,'Sales Data'!$BD$6:$BD$10000,$C$7),0)
B37: ↳ Sponsored Brands | C37: =IFERROR(SUMIFS('Sub Expenses'!$E$6:$E$10000,'Sub Expenses'!$B$6:$B$10000,$D$7,'Sub Expenses'!$C$6:$C$10000,"Advertising cost",'Sub Expenses'!$D$6:$D$10000,"Sponsored Brands",'Sub Expenses'!$J$6:$J$10000,$B$7,'Sub Expenses'!$K$6:$K$10000,$C$7),0) | D37: =IFERROR(C37/SUMIFS('Main Expenses'!$E$6:$E$10000,'Main Expenses'!$B$6:$B$10000,$D$7,'Main Expenses'!$K$6:$K$10000,$B$7,'Main Expenses'!$L$6:$L$10000,$C$7),0) | J37: Sponsored Display (same day) | K37: =IFERROR(SUMIFS('Sales Data'!$E$6:$E$10000,'Sales Data'!$B$6:$B$10000,$D$7,'Sales Data'!$D$6:$D$10000,"Sponsored Display (same day)",'Sales Data'!$BC$6:$BC$10000,$B$7,'Sales Data'!$BD$6:$BD$10000,$C$7),0) | L37: =IFERROR(K37/SUMIFS('Sales Data'!$E$6:$E$10000,'Sales Data'!$B$6:$B$10000,$D$7,'Sales Data'!$BC$6:$BC$10000,$B$7,'Sales Data'!$BD$6:$BD$10000,$C$7),0)
B38: ↳ Sponsored Brands Video | C38: =IFERROR(SUMIFS('Sub Expenses'!$E$6:$E$10000,'Sub Expenses'!$B$6:$B$10000,$D$7,'Sub Expenses'!$C$6:$C$10000,"Advertising cost",'Sub Expenses'!$D$6:$D$10000,"Sponsored Brands Video",'Sub Expenses'!$J$6:$J$10000,$B$7,'Sub Expenses'!$K$6:$K$10000,$C$7),0) | D38: =IFERROR(C38/SUMIFS('Main Expenses'!$E$6:$E$10000,'Main Expenses'!$B$6:$B$10000,$D$7,'Main Expenses'!$K$6:$K$10000,$B$7,'Main Expenses'!$L$6:$L$10000,$C$7),0)
B39: ↳ Sponsored Display | C39: =IFERROR(SUMIFS('Sub Expenses'!$E$6:$E$10000,'Sub Expenses'!$B$6:$B$10000,$D$7,'Sub Expenses'!$C$6:$C$10000,"Advertising cost",'Sub Expenses'!$D$6:$D$10000,"Sponsored Display",'Sub Expenses'!$J$6:$J$10000,$B$7,'Sub Expenses'!$K$6:$K$10000,$C$7),0) | D39: =IFERROR(C39/SUMIFS('Main Expenses'!$E$6:$E$10000,'Main Expenses'!$B$6:$B$10000,$D$7,'Main Expenses'!$K$6:$K$10000,$B$7,'Main Expenses'!$L$6:$L$10000,$C$7),0)
B40: ↳ Sponsored Products | C40: =IFERROR(SUMIFS('Sub Expenses'!$E$6:$E$10000,'Sub Expenses'!$B$6:$B$10000,$D$7,'Sub Expenses'!$C$6:$C$10000,"Advertising cost",'Sub Expenses'!$D$6:$D$10000,"Sponsored Products",'Sub Expenses'!$J$6:$J$10000,$B$7,'Sub Expenses'!$K$6:$K$10000,$C$7),0) | D40: =IFERROR(C40/SUMIFS('Main Expenses'!$E$6:$E$10000,'Main Expenses'!$B$6:$B$10000,$D$7,'Main Expenses'!$K$6:$K$10000,$B$7,'Main Expenses'!$L$6:$L$10000,$C$7),0)
B41: Refund cost | C41: =IFERROR(SUMIFS('Main Expenses'!$E$6:$E$10000,'Main Expenses'!$B$6:$B$10000,$D$7,'Main Expenses'!$D$6:$D$10000,"Refund cost",'Main Expenses'!$K$6:$K$10000,$B$7,'Main Expenses'!$L$6:$L$10000,$C$7),0) | D41: =IFERROR(C41/SUMIFS('Main Expenses'!$E$6:$E$10000,'Main Expenses'!$B$6:$B$10000,$D$7,'Main Expenses'!$K$6:$K$10000,$B$7,'Main Expenses'!$L$6:$L$10000,$C$7),0)
B42: ↳ Promotion | C42: =IFERROR(SUMIFS('Sub Expenses'!$E$6:$E$10000,'Sub Expenses'!$B$6:$B$10000,$D$7,'Sub Expenses'!$C$6:$C$10000,"Refund cost",'Sub Expenses'!$D$6:$D$10000,"Promotion",'Sub Expenses'!$J$6:$J$10000,$B$7,'Sub Expenses'!$K$6:$K$10000,$C$7),0) | D42: =IFERROR(C42/SUMIFS('Main Expenses'!$E$6:$E$10000,'Main Expenses'!$B$6:$B$10000,$D$7,'Main Expenses'!$K$6:$K$10000,$B$7,'Main Expenses'!$L$6:$L$10000,$C$7),0)
